<sdf version='1.6'>
  <world name='default'>
    <light name='sun' type='directional'>
      <cast_shadows>1</cast_shadows>
      <pose frame=''>0 0 10 0 -0 0</pose>
      <diffuse>0.8 0.8 0.8 1</diffuse>
      <specular>0.1 0.1 0.1 1</specular>
      <attenuation>
        <range>1000</range>
        <constant>0.9</constant>
        <linear>0.01</linear>
        <quadratic>0.001</quadratic>
      </attenuation>
      <direction>-0.5 0.5 -1</direction>
    </light>
    <model name='ground_plane'>
      <static>1</static>
      <link name='link'>
        <collision name='collision'>
          <geometry>
            <plane>
              <normal>0 0 1</normal>
              <size>100 100</size>
            </plane>
          </geometry>
          <surface>
            <friction>
              <ode>
                <mu>100</mu>
                <mu2>50</mu2>
              </ode>
              <torsional>
                <ode/>
              </torsional>
            </friction>
            <contact>
              <ode/>
            </contact>
            <bounce/>
          </surface>
          <max_contacts>10</max_contacts>
        </collision>
        <visual name='visual'>
          <cast_shadows>0</cast_shadows>
          <geometry>
            <plane>
              <normal>0 0 1</normal>
              <size>100 100</size>
            </plane>
          </geometry>
          <material>
            <script>
              <uri>file://media/materials/scripts/gazebo.material</uri>
              <name>Gazebo/Grey</name>
            </script>
          </material>
        </visual>
        <self_collide>0</self_collide>
        <kinematic>0</kinematic>
        <gravity>1</gravity>
      </link>
    </model>
    <gravity>0 0 -9.8</gravity>
    <magnetic_field>6e-06 2.3e-05 -4.2e-05</magnetic_field>
    <atmosphere type='adiabatic'/>
    <physics name='default_physics' default='0' type='ode'>
      <max_step_size>0.001</max_step_size>
      <real_time_factor>1</real_time_factor>
      <real_time_update_rate>1000</real_time_update_rate>
    </physics>
    <scene>
      <ambient>0.4 0.4 0.4 1</ambient>
      <background>0.7 0.7 0.7 1</background>
      <shadows>1</shadows>
    </scene>
    <spherical_coordinates>
      <surface_model>EARTH_WGS84</surface_model>
      <latitude_deg>0</latitude_deg>
      <longitude_deg>0</longitude_deg>
      <elevation>0</elevation>
      <heading_deg>0</heading_deg>
    </spherical_coordinates>
    <model name='Jack2'>
      <self_collide>0</self_collide>
      <static>0</static>
      <link name='fork1'>
        <pose frame=''>0 0 0.12 0 -0 0</pose>
        <collision name='fork1_collision'>
          <geometry>
            <box>
              <size>1 0.2 0.05</size>
            </box>
          </geometry>
          <max_contacts>10</max_contacts>
          <surface>
            <contact>
              <ode/>
            </contact>
            <bounce/>
            <friction>
              <torsional>
                <ode/>
              </torsional>
              <ode/>
            </friction>
          </surface>
        </collision>
        <visual name='fork1_visual'>
          <geometry>
            <box>
              <size>1 0.2 0.05</size>
            </box>
          </geometry>
        </visual>
        <collision name='fork1_holeright_collision'>
          <pose frame=''>0.6 0.075 0 0 -0 0</pose>
          <geometry>
            <box>
              <size>0.2 0.05 0.05</size>
            </box>
          </geometry>
          <max_contacts>10</max_contacts>
          <surface>
            <contact>
              <ode/>
            </contact>
            <bounce/>
            <friction>
              <torsional>
                <ode/>
              </torsional>
              <ode/>
            </friction>
          </surface>
        </collision>
        <visual name='fork1_holeright_visual'>
          <pose frame=''>0.6 0.075 0 0 -0 0</pose>
          <geometry>
            <box>
              <size>0.2 0.05 0.05</size>
            </box>
          </geometry>
        </visual>
        <collision name='fork1_holeleft_collision'>
          <pose frame=''>0.6 -0.075 0 0 -0 0</pose>
          <geometry>
            <box>
              <size>0.2 0.05 0.05</size>
            </box>
          </geometry>
          <max_contacts>10</max_contacts>
          <surface>
            <contact>
              <ode/>
            </contact>
            <bounce/>
            <friction>
              <torsional>
                <ode/>
              </torsional>
              <ode/>
            </friction>
          </surface>
        </collision>
        <visual name='fork1_holeleft_visual'>
          <pose frame=''>0.6 -0.075 0 0 -0 0</pose>
          <geometry>
            <box>
              <size>0.2 0.05 0.05</size>
            </box>
          </geometry>
        </visual>
        <collision name='fork1_end_collision'>
          <pose frame=''>0.75 0 0 0 -0 0</pose>
          <geometry>
            <box>
              <size>0.1 0.2 0.05</size>
            </box>
          </geometry>
          <max_contacts>10</max_contacts>
          <surface>
            <contact>
              <ode/>
            </contact>
            <bounce/>
            <friction>
              <torsional>
                <ode/>
              </torsional>
              <ode/>
            </friction>
          </surface>
        </collision>
        <visual name='fork1_end_visual'>
          <pose frame=''>0.75 0 0 0 -0 0</pose>
          <geometry>
            <box>
              <size>0.1 0.2 0.05</size>
            </box>
          </geometry>
        </visual>
        <collision name='fork1_wheelholder_cylinder_collision'>
          <pose frame=''>0.3 0 -0.025 3.14159 1.57079 -1.57079</pose>
          <geometry>
            <cylinder>
              <radius>0.02</radius>
              <length>0.2</length>
            </cylinder>
          </geometry>
          <max_contacts>10</max_contacts>
          <surface>
            <contact>
              <ode/>
            </contact>
            <bounce/>
            <friction>
              <torsional>
                <ode/>
              </torsional>
              <ode/>
            </friction>
          </surface>
        </collision>
        <visual name='fork1_wheelholder_cylinder__visual'>
          <pose frame=''>0.3 0 -0.025 3.14159 1.57079 -1.57079</pose>
          <geometry>
            <cylinder>
              <radius>0.02</radius>
              <length>0.2</length>
            </cylinder>
          </geometry>
        </visual>
        <self_collide>0</self_collide>
        <inertial>
          <inertia>
            <ixx>1</ixx>
            <ixy>0</ixy>
            <ixz>0</ixz>
            <iyy>1</iyy>
            <iyz>0</iyz>
            <izz>1</izz>
          </inertia>
          <mass>1</mass>
        </inertial>
        <kinematic>0</kinematic>
        <gravity>1</gravity>
      </link>
      <link name='fork1_wheelholder'>
        <pose frame=''>0.4 0 0.07 0 -0 0</pose>
        <collision name='fork1_wheelholder_collision'>
          <geometry>
            <box>
              <size>0.2 0.2 0.01</size>
            </box>
          </geometry>
          <max_contacts>10</max_contacts>
          <surface>
            <contact>
              <ode/>
            </contact>
            <bounce/>
            <friction>
              <torsional>
                <ode/>
              </torsional>
              <ode/>
            </friction>
          </surface>
        </collision>
        <visual name='fork1_wheelholder_visual'>
          <geometry>
            <box>
              <size>0.2 0.2 0.01</size>
            </box>
          </geometry>
        </visual>
        <collision name='fork1_wheelholder_holeright_collision'>
          <pose frame=''>0.15 0.075 0 0 -0 0</pose>
          <geometry>
            <box>
              <size>0.1 0.05 0.01</size>
            </box>
          </geometry>
          <max_contacts>10</max_contacts>
          <surface>
            <contact>
              <ode/>
            </contact>
            <bounce/>
            <friction>
              <torsional>
                <ode/>
              </torsional>
              <ode/>
            </friction>
          </surface>
        </collision>
        <visual name='fork1_wheelholder_holeright_visual'>
          <pose frame=''>0.15 0.075 0 0 -0 0</pose>
          <geometry>
            <box>
              <size>0.1 0.05 0.01</size>
            </box>
          </geometry>
        </visual>
        <collision name='fork1_wheelholder_holeleft_collision'>
          <pose frame=''>0.15 -0.075 0 0 -0 0</pose>
          <geometry>
            <box>
              <size>0.1 0.05 0.01</size>
            </box>
          </geometry>
          <max_contacts>10</max_contacts>
          <surface>
            <contact>
              <ode/>
            </contact>
            <bounce/>
            <friction>
              <torsional>
                <ode/>
              </torsional>
              <ode/>
            </friction>
          </surface>
        </collision>
        <visual name='fork1_wheelholder_holeleft_visual'>
          <pose frame=''>0.15 -0.075 0 0 -0 0</pose>
          <geometry>
            <box>
              <size>0.1 0.05 0.01</size>
            </box>
          </geometry>
        </visual>
        <self_collide>0</self_collide>
        <inertial>
          <inertia>
            <ixx>1</ixx>
            <ixy>0</ixy>
            <ixz>0</ixz>
            <iyy>1</iyy>
            <iyz>0</iyz>
            <izz>1</izz>
          </inertia>
          <mass>1</mass>
        </inertial>
        <kinematic>0</kinematic>
        <gravity>1</gravity>
      </link>
      <link name='fork1_prismatic_cylinder_top'>
        <pose frame=''>0.48 0 0.09 3.14159 1.57079 -1.57079</pose>
        <collision name='fork1_prismatic_cylinder_top_collision'>
          <geometry>
            <cylinder>
              <radius>0.005</radius>
              <length>0.02</length>
            </cylinder>
          </geometry>
          <max_contacts>10</max_contacts>
          <surface>
            <contact>
              <ode/>
            </contact>
            <bounce/>
            <friction>
              <torsional>
                <ode/>
              </torsional>
              <ode/>
            </friction>
          </surface>
        </collision>
        <visual name='fork1_prismatic_cylinder_top_visual'>
          <geometry>
            <cylinder>
              <radius>0.005</radius>
              <length>0.02</length>
            </cylinder>
          </geometry>
        </visual>
        <self_collide>0</self_collide>
        <inertial>
          <inertia>
            <ixx>1</ixx>
            <ixy>0</ixy>
            <ixz>0</ixz>
            <iyy>1</iyy>
            <iyz>0</iyz>
            <izz>1</izz>
          </inertia>
          <mass>1</mass>
        </inertial>
        <kinematic>0</kinematic>
        <gravity>1</gravity>
      </link>
      <link name='fork1_prismatic_cylinder_bottom'>
        <pose frame=''>0.48 0 0.08 3.14159 1.57079 -1.57079</pose>
        <collision name='ork1_prismatic_cylinder_bottom_collision'>
          <geometry>
            <cylinder>
              <radius>0.005</radius>
              <length>0.02</length>
            </cylinder>
          </geometry>
          <max_contacts>10</max_contacts>
          <surface>
            <contact>
              <ode/>
            </contact>
            <bounce/>
            <friction>
              <torsional>
                <ode/>
              </torsional>
              <ode/>
            </friction>
          </surface>
        </collision>
        <visual name='ork1_prismatic_cylinder_bottom_visual'>
          <geometry>
            <cylinder>
              <radius>0.005</radius>
              <length>0.02</length>
            </cylinder>
          </geometry>
        </visual>
        <self_collide>0</self_collide>
        <inertial>
          <inertia>
            <ixx>1</ixx>
            <ixy>0</ixy>
            <ixz>0</ixz>
            <iyy>1</iyy>
            <iyz>0</iyz>
            <izz>1</izz>
          </inertia>
          <mass>1</mass>
        </inertial>
        <kinematic>0</kinematic>
        <gravity>1</gravity>
      </link>
      <link name='fork1_wheel'>
        <pose frame=''>0.6 0 0.07 3.14159 1.57079 -1.57079</pose>
        <collision name='fork2_wheel_collision'>
          <geometry>
            <cylinder>
              <radius>0.07</radius>
              <length>0.09</length>
            </cylinder>
          </geometry>
          <max_contacts>10</max_contacts>
          <surface>
            <contact>
              <ode/>
            </contact>
            <bounce/>
            <friction>
              <torsional>
                <ode/>
              </torsional>
              <ode/>
            </friction>
          </surface>
        </collision>
        <visual name='fork2_wheel_visual'>
          <geometry>
            <cylinder>
              <radius>0.07</radius>
              <length>0.09</length>
            </cylinder>
          </geometry>
        </visual>
        <self_collide>0</self_collide>
        <inertial>
          <inertia>
            <ixx>1</ixx>
            <ixy>0</ixy>
            <ixz>0</ixz>
            <iyy>1</iyy>
            <iyz>0</iyz>
            <izz>1</izz>
          </inertia>
          <mass>1</mass>
        </inertial>
        <kinematic>0</kinematic>
        <gravity>1</gravity>
      </link>
      <joint name='fork1_wheelholder_hinge' type='revolute'>
        <pose frame=''>-0.1 0 0.005 0 -0 0</pose>
        <child>fork1_wheelholder</child>
        <parent>fork1</parent>
        <axis>
          <xyz>0 1 0</xyz>
          <use_parent_model_frame>1</use_parent_model_frame>
          <limit>
            <lower>-1e+16</lower>
            <upper>1e+16</upper>
          </limit>
          <dynamics>
            <spring_reference>0</spring_reference>
            <spring_stiffness>0</spring_stiffness>
          </dynamics>
        </axis>
      </joint>
      <joint name='fork1_prismatic_cylinder_top_hinge' type='revolute'>
        <pose frame=''>-0 0 0 0 -0 0</pose>
        <child>fork1_prismatic_cylinder_top</child>
        <parent>fork1</parent>
        <axis>
          <xyz>0 1 0</xyz>
          <use_parent_model_frame>1</use_parent_model_frame>
          <limit>
            <lower>-1e+16</lower>
            <upper>1e+16</upper>
          </limit>
          <dynamics>
            <spring_reference>0</spring_reference>
            <spring_stiffness>0</spring_stiffness>
          </dynamics>
        </axis>
      </joint>
      <joint name='fork1_prismatic_cylinder_bottom_hinge' type='revolute'>
        <pose frame=''>-0 0 0 0 -0 0</pose>
        <child>fork1_prismatic_cylinder_bottom</child>
        <parent>fork1_wheelholder</parent>
        <axis>
          <xyz>0 1 0</xyz>
          <use_parent_model_frame>1</use_parent_model_frame>
          <limit>
            <lower>-1e+16</lower>
            <upper>1e+16</upper>
          </limit>
          <dynamics>
            <spring_reference>0</spring_reference>
            <spring_stiffness>0</spring_stiffness>
          </dynamics>
        </axis>
      </joint>
      <joint name='fork1_wheel_joint' type='revolute'>
        <pose frame=''>-0 0 0 0 -0 0</pose>
        <child>fork1_wheel</child>
        <parent>fork1_wheelholder</parent>
        <axis>
          <xyz>0 1 0</xyz>
          <use_parent_model_frame>1</use_parent_model_frame>
          <limit>
            <lower>-1e+16</lower>
            <upper>1e+16</upper>
          </limit>
          <dynamics>
            <spring_reference>0</spring_reference>
            <spring_stiffness>0</spring_stiffness>
          </dynamics>
        </axis>
      </joint>
      <joint name='fork1_prismatic' type='prismatic'>
        <pose frame=''>0 0 -0.01 0 -0 0</pose>
        <child>fork1_prismatic_cylinder_top</child>
        <parent>fork1_prismatic_cylinder_bottom</parent>
        <axis>
          <xyz>0 0 1</xyz>
          <limit>
            <upper>0.05</upper>
            <lower>0</lower>
            <velocity>0.001</velocity>
          </limit>
          <use_parent_model_frame>1</use_parent_model_frame>
          <dynamics>
            <spring_reference>0</spring_reference>
            <spring_stiffness>0</spring_stiffness>
          </dynamics>
        </axis>
      </joint>
      <link name='fork2'>
        <pose frame=''>0 0.6 0.12 0 -0 0</pose>
        <collision name='fork2_collision'>
          <geometry>
            <box>
              <size>1 0.2 0.05</size>
            </box>
          </geometry>
          <max_contacts>10</max_contacts>
          <surface>
            <contact>
              <ode/>
            </contact>
            <bounce/>
            <friction>
              <torsional>
                <ode/>
              </torsional>
              <ode/>
            </friction>
          </surface>
        </collision>
        <visual name='fork2_visual'>
          <geometry>
            <box>
              <size>1 0.2 0.05</size>
            </box>
          </geometry>
        </visual>
        <collision name='fork2_holeright_collision'>
          <pose frame=''>0.6 0.075 0 0 -0 0</pose>
          <geometry>
            <box>
              <size>0.2 0.05 0.05</size>
            </box>
          </geometry>
          <max_contacts>10</max_contacts>
          <surface>
            <contact>
              <ode/>
            </contact>
            <bounce/>
            <friction>
              <torsional>
                <ode/>
              </torsional>
              <ode/>
            </friction>
          </surface>
        </collision>
        <visual name='fork2_holeright_visual'>
          <pose frame=''>0.6 0.075 0 0 -0 0</pose>
          <geometry>
            <box>
              <size>0.2 0.05 0.05</size>
            </box>
          </geometry>
        </visual>
        <collision name='fork2_holeleft_collision'>
          <pose frame=''>0.6 -0.075 0 0 -0 0</pose>
          <geometry>
            <box>
              <size>0.2 0.05 0.05</size>
            </box>
          </geometry>
          <max_contacts>10</max_contacts>
          <surface>
            <contact>
              <ode/>
            </contact>
            <bounce/>
            <friction>
              <torsional>
                <ode/>
              </torsional>
              <ode/>
            </friction>
          </surface>
        </collision>
        <visual name='fork2_holeleft_visual'>
          <pose frame=''>0.6 -0.075 0 0 -0 0</pose>
          <geometry>
            <box>
              <size>0.2 0.05 0.05</size>
            </box>
          </geometry>
        </visual>
        <collision name='fork2_end_collision'>
          <pose frame=''>0.75 0 0 0 -0 0</pose>
          <geometry>
            <box>
              <size>0.1 0.2 0.05</size>
            </box>
          </geometry>
          <max_contacts>10</max_contacts>
          <surface>
            <contact>
              <ode/>
            </contact>
            <bounce/>
            <friction>
              <torsional>
                <ode/>
              </torsional>
              <ode/>
            </friction>
          </surface>
        </collision>
        <visual name='fork2_end_visual'>
          <pose frame=''>0.75 0 0 0 -0 0</pose>
          <geometry>
            <box>
              <size>0.1 0.2 0.05</size>
            </box>
          </geometry>
        </visual>
        <collision name='fork2_wheelholder_cylinder_collision'>
          <pose frame=''>0.3 0 -0.025 3.14159 1.57079 -1.57079</pose>
          <geometry>
            <cylinder>
              <radius>0.02</radius>
              <length>0.2</length>
            </cylinder>
          </geometry>
          <max_contacts>10</max_contacts>
          <surface>
            <contact>
              <ode/>
            </contact>
            <bounce/>
            <friction>
              <torsional>
                <ode/>
              </torsional>
              <ode/>
            </friction>
          </surface>
        </collision>
        <visual name='fork2_wheelholder_cylinder__visual'>
          <pose frame=''>0.3 0 -0.025 3.14159 1.57079 -1.57079</pose>
          <geometry>
            <cylinder>
              <radius>0.02</radius>
              <length>0.2</length>
            </cylinder>
          </geometry>
        </visual>
        <self_collide>0</self_collide>
        <inertial>
          <inertia>
            <ixx>1</ixx>
            <ixy>0</ixy>
            <ixz>0</ixz>
            <iyy>1</iyy>
            <iyz>0</iyz>
            <izz>1</izz>
          </inertia>
          <mass>1</mass>
        </inertial>
        <kinematic>0</kinematic>
        <gravity>1</gravity>
      </link>
      <link name='fork2_wheelholder'>
        <pose frame=''>0.4 0.6 0.07 0 -0 0</pose>
        <collision name='fork2_wheelholder_collision'>
          <geometry>
            <box>
              <size>0.2 0.2 0.01</size>
            </box>
          </geometry>
          <max_contacts>10</max_contacts>
          <surface>
            <contact>
              <ode/>
            </contact>
            <bounce/>
            <friction>
              <torsional>
                <ode/>
              </torsional>
              <ode/>
            </friction>
          </surface>
        </collision>
        <visual name='fork2_wheelholder_visual'>
          <geometry>
            <box>
              <size>0.2 0.2 0.01</size>
            </box>
          </geometry>
        </visual>
        <collision name='fork2_wheelholder_holeright_collision'>
          <pose frame=''>0.15 0.075 0 0 -0 0</pose>
          <geometry>
            <box>
              <size>0.1 0.05 0.01</size>
            </box>
          </geometry>
          <max_contacts>10</max_contacts>
          <surface>
            <contact>
              <ode/>
            </contact>
            <bounce/>
            <friction>
              <torsional>
                <ode/>
              </torsional>
              <ode/>
            </friction>
          </surface>
        </collision>
        <visual name='fork2_wheelholder_holeright_visual'>
          <pose frame=''>0.15 0.075 0 0 -0 0</pose>
          <geometry>
            <box>
              <size>0.1 0.05 0.01</size>
            </box>
          </geometry>
        </visual>
        <collision name='fork2_wheelholder_holeleft_collision'>
          <pose frame=''>0.15 -0.075 0 0 -0 0</pose>
          <geometry>
            <box>
              <size>0.1 0.05 0.01</size>
            </box>
          </geometry>
          <max_contacts>10</max_contacts>
          <surface>
            <contact>
              <ode/>
            </contact>
            <bounce/>
            <friction>
              <torsional>
                <ode/>
              </torsional>
              <ode/>
            </friction>
          </surface>
        </collision>
        <visual name='fork2_wheelholder_holeleft_visual'>
          <pose frame=''>0.15 -0.075 0 0 -0 0</pose>
          <geometry>
            <box>
              <size>0.1 0.05 0.01</size>
            </box>
          </geometry>
        </visual>
        <self_collide>0</self_collide>
        <inertial>
          <inertia>
            <ixx>1</ixx>
            <ixy>0</ixy>
            <ixz>0</ixz>
            <iyy>1</iyy>
            <iyz>0</iyz>
            <izz>1</izz>
          </inertia>
          <mass>1</mass>
        </inertial>
        <kinematic>0</kinematic>
        <gravity>1</gravity>
      </link>
      <link name='fork2_prismatic_cylinder_top'>
        <pose frame=''>0.48 0.6 0.09 3.14159 1.57079 -1.57079</pose>
        <collision name='fork2_prismatic_cylinder_top_collision'>
          <geometry>
            <cylinder>
              <radius>0.005</radius>
              <length>0.02</length>
            </cylinder>
          </geometry>
          <max_contacts>10</max_contacts>
          <surface>
            <contact>
              <ode/>
            </contact>
            <bounce/>
            <friction>
              <torsional>
                <ode/>
              </torsional>
              <ode/>
            </friction>
          </surface>
        </collision>
        <visual name='fork2_prismatic_cylinder_top_visual'>
          <geometry>
            <cylinder>
              <radius>0.005</radius>
              <length>0.02</length>
            </cylinder>
          </geometry>
        </visual>
        <self_collide>0</self_collide>
        <inertial>
          <inertia>
            <ixx>1</ixx>
            <ixy>0</ixy>
            <ixz>0</ixz>
            <iyy>1</iyy>
            <iyz>0</iyz>
            <izz>1</izz>
          </inertia>
          <mass>1</mass>
        </inertial>
        <kinematic>0</kinematic>
        <gravity>1</gravity>
      </link>
      <link name='fork2_prismatic_cylinder_bottom'>
        <pose frame=''>0.48 0.6 0.08 3.14159 1.57079 -1.57079</pose>
        <collision name='fork2_prismatic_cylinder_bottom_collision'>
          <geometry>
            <cylinder>
              <radius>0.005</radius>
              <length>0.02</length>
            </cylinder>
          </geometry>
          <max_contacts>10</max_contacts>
          <surface>
            <contact>
              <ode/>
            </contact>
            <bounce/>
            <friction>
              <torsional>
                <ode/>
              </torsional>
              <ode/>
            </friction>
          </surface>
        </collision>
        <visual name='fork2_prismatic_cylinder_bottom_visual'>
          <geometry>
            <cylinder>
              <radius>0.005</radius>
              <length>0.02</length>
            </cylinder>
          </geometry>
        </visual>
        <self_collide>0</self_collide>
        <inertial>
          <inertia>
            <ixx>1</ixx>
            <ixy>0</ixy>
            <ixz>0</ixz>
            <iyy>1</iyy>
            <iyz>0</iyz>
            <izz>1</izz>
          </inertia>
          <mass>1</mass>
        </inertial>
        <kinematic>0</kinematic>
        <gravity>1</gravity>
      </link>
      <link name='fork2_wheel'>
        <pose frame=''>0.6 0.6 0.07 3.14159 1.57079 -1.57079</pose>
        <collision name='fork2_wheel_collision'>
          <geometry>
            <cylinder>
              <radius>0.07</radius>
              <length>0.09</length>
            </cylinder>
          </geometry>
          <max_contacts>10</max_contacts>
          <surface>
            <contact>
              <ode/>
            </contact>
            <bounce/>
            <friction>
              <torsional>
                <ode/>
              </torsional>
              <ode/>
            </friction>
          </surface>
        </collision>
        <visual name='fork2_wheel_visual'>
          <geometry>
            <cylinder>
              <radius>0.07</radius>
              <length>0.09</length>
            </cylinder>
          </geometry>
        </visual>
        <self_collide>0</self_collide>
        <inertial>
          <inertia>
            <ixx>1</ixx>
            <ixy>0</ixy>
            <ixz>0</ixz>
            <iyy>1</iyy>
            <iyz>0</iyz>
            <izz>1</izz>
          </inertia>
          <mass>1</mass>
        </inertial>
        <kinematic>0</kinematic>
        <gravity>1</gravity>
      </link>
      <joint name='fork2_wheelholder_hinge' type='revolute'>
        <pose frame=''>-0.1 0 0.005 0 -0 0</pose>
        <child>fork2_wheelholder</child>
        <parent>fork2</parent>
        <axis>
          <xyz>0 1 0</xyz>
          <use_parent_model_frame>1</use_parent_model_frame>
          <limit>
            <lower>-1e+16</lower>
            <upper>1e+16</upper>
          </limit>
          <dynamics>
            <spring_reference>0</spring_reference>
            <spring_stiffness>0</spring_stiffness>
          </dynamics>
        </axis>
      </joint>
      <joint name='fork2_prismatic_cylinder_top_hinge' type='revolute'>
        <pose frame=''>-0 0 0 0 -0 0</pose>
        <child>fork2_prismatic_cylinder_top</child>
        <parent>fork2</parent>
        <axis>
          <xyz>0 1 0</xyz>
          <use_parent_model_frame>1</use_parent_model_frame>
          <limit>
            <lower>-1e+16</lower>
            <upper>1e+16</upper>
          </limit>
          <dynamics>
            <spring_reference>0</spring_reference>
            <spring_stiffness>0</spring_stiffness>
          </dynamics>
        </axis>
      </joint>
      <joint name='fork2_prismatic_cylinder_bottom_hinge' type='revolute'>
        <pose frame=''>-0 0 0 0 -0 0</pose>
        <child>fork2_prismatic_cylinder_bottom</child>
        <parent>fork2_wheelholder</parent>
        <axis>
          <xyz>0 1 0</xyz>
          <use_parent_model_frame>1</use_parent_model_frame>
          <limit>
            <lower>-1e+16</lower>
            <upper>1e+16</upper>
          </limit>
          <dynamics>
            <spring_reference>0</spring_reference>
            <spring_stiffness>0</spring_stiffness>
          </dynamics>
        </axis>
      </joint>
      <joint name='fork2_wheel_joint' type='revolute'>
        <pose frame=''>-0 0 0 0 -0 0</pose>
        <child>fork2_wheel</child>
        <parent>fork2_wheelholder</parent>
        <axis>
          <xyz>0 1 0</xyz>
          <use_parent_model_frame>1</use_parent_model_frame>
          <limit>
            <lower>-1e+16</lower>
            <upper>1e+16</upper>
          </limit>
          <dynamics>
            <spring_reference>0</spring_reference>
            <spring_stiffness>0</spring_stiffness>
          </dynamics>
        </axis>
      </joint>
      <joint name='fork2_prismatic' type='prismatic'>
        <pose frame=''>0 0 -0.01 0 -0 0</pose>
        <child>fork2_prismatic_cylinder_top</child>
        <parent>fork2_prismatic_cylinder_bottom</parent>
        <axis>
          <xyz>0 0 1</xyz>
          <limit>
            <upper>0.05</upper>
            <lower>0</lower>
            <velocity>0.001</velocity>
          </limit>
          <use_parent_model_frame>1</use_parent_model_frame>
          <dynamics>
            <spring_reference>0</spring_reference>
            <spring_stiffness>0</spring_stiffness>
          </dynamics>
        </axis>
      </joint>
      <link name='mid_prismatic'>
        <pose frame=''>-0.45 0.3 0.345 0 -0 0</pose>
        <collision name='mid_prismatic_collision'>
          <pose frame=''>0 0 0 0 -0 0</pose>
          <geometry>
            <box>
              <size>0.01 0.01 0.01</size>
            </box>
          </geometry>
          <max_contacts>10</max_contacts>
          <surface>
            <contact>
              <ode/>
            </contact>
            <bounce/>
            <friction>
              <torsional>
                <ode/>
              </torsional>
              <ode/>
            </friction>
          </surface>
        </collision>
        <visual name='mid_prismatic_visual'>
          <pose frame=''>-0 0 0 0 -0 0</pose>
          <geometry>
            <box>
              <size>0.01 0.01 0.01</size>
            </box>
          </geometry>
        </visual>
        <self_collide>0</self_collide>
        <inertial>
          <inertia>
            <ixx>1</ixx>
            <ixy>0</ixy>
            <ixz>0</ixz>
            <iyy>1</iyy>
            <iyz>0</iyz>
            <izz>1</izz>
          </inertia>
          <mass>1</mass>
        </inertial>
        <kinematic>0</kinematic>
        <gravity>1</gravity>
      </link>
      <link name='mid'>
        <pose frame=''>-0.45 0.3 0.345 0 -0 0</pose>
        <collision name='mid_wall_collision'>
          <geometry>
            <box>
              <size>0.1 0.6 0.5</size>
            </box>
          </geometry>
          <max_contacts>10</max_contacts>
          <surface>
            <contact>
              <ode/>
            </contact>
            <bounce/>
            <friction>
              <torsional>
                <ode/>
              </torsional>
              <ode/>
            </friction>
          </surface>
        </collision>
        <visual name='mid_wall_visual'>
          <geometry>
            <box>
              <size>0.1 0.6 0.5</size>
            </box>
          </geometry>
        </visual>
        <collision name='mid_wall_distance_collision'>
          <pose frame=''>0.07 0 0.1 0 -0 0</pose>
          <geometry>
            <box>
              <size>0.1 0.1 0.1</size>
            </box>
          </geometry>
          <max_contacts>10</max_contacts>
          <surface>
            <contact>
              <ode/>
            </contact>
            <bounce/>
            <friction>
              <torsional>
                <ode/>
              </torsional>
              <ode/>
            </friction>
          </surface>
        </collision>
        <visual name='mid_wall_distance_visual'>
          <pose frame=''>0.07 0 0.1 0 -0 0</pose>
          <geometry>
            <box>
              <size>0.1 0.1 0.1</size>
            </box>
          </geometry>
        </visual>
        <collision name='mid_top_collision'>
          <pose frame=''>-0.15 0 0.275 0 -0 0</pose>
          <geometry>
            <box>
              <size>0.4 0.6 0.05</size>
            </box>
          </geometry>
          <max_contacts>10</max_contacts>
          <surface>
            <contact>
              <ode/>
            </contact>
            <bounce/>
            <friction>
              <torsional>
                <ode/>
              </torsional>
              <ode/>
            </friction>
          </surface>
        </collision>
        <visual name='mid_top_visual'>
          <pose frame=''>-0.15 0 0.275 0 -0 0</pose>
          <geometry>
            <box>
              <size>0.4 0.6 0.05</size>
            </box>
          </geometry>
        </visual>
        <self_collide>0</self_collide>
        <inertial>
          <inertia>
            <ixx>1</ixx>
            <ixy>0</ixy>
            <ixz>0</ixz>
            <iyy>1</iyy>
            <iyz>0</iyz>
            <izz>1</izz>
          </inertia>
          <mass>1</mass>
        </inertial>
        <kinematic>0</kinematic>
        <gravity>1</gravity>
      </link>
      <link name='differential_body'>
        <pose frame=''>-0.7 0.3 0.12 0 -0 0</pose>
        <collision name='differential_body_collision'>
          <geometry>
            <box>
              <size>0.1 0.02 0.1</size>
            </box>
          </geometry>
          <max_contacts>10</max_contacts>
          <surface>
            <contact>
              <ode/>
            </contact>
            <bounce/>
            <friction>
              <torsional>
                <ode/>
              </torsional>
              <ode/>
            </friction>
          </surface>
        </collision>
        <visual name='differential_body_visual'>
          <geometry>
            <box>
              <size>0.1 0.02 0.1</size>
            </box>
          </geometry>
        </visual>
        <self_collide>0</self_collide>
        <inertial>
          <inertia>
            <ixx>1</ixx>
            <ixy>0</ixy>
            <ixz>0</ixz>
            <iyy>1</iyy>
            <iyz>0</iyz>
            <izz>1</izz>
          </inertia>
          <mass>1</mass>
        </inertial>
        <kinematic>0</kinematic>
        <gravity>1</gravity>
      </link>
      <link name='differential_cylinder'>
        <pose frame=''>-0.7 0.3 0.3825 0 -0 0</pose>
        <collision name='differential_cylinder_collision'>
          <geometry>
            <cylinder>
              <radius>0.01</radius>
              <length>0.425</length>
            </cylinder>
          </geometry>
          <max_contacts>10</max_contacts>
          <surface>
            <contact>
              <ode/>
            </contact>
            <bounce/>
            <friction>
              <torsional>
                <ode/>
              </torsional>
              <ode/>
            </friction>
          </surface>
        </collision>
        <visual name='differential_cylinder_visual'>
          <geometry>
            <cylinder>
              <radius>0.01</radius>
              <length>0.425</length>
            </cylinder>
          </geometry>
        </visual>
        <self_collide>0</self_collide>
        <inertial>
          <inertia>
            <ixx>1</ixx>
            <ixy>0</ixy>
            <ixz>0</ixz>
            <iyy>1</iyy>
            <iyz>0</iyz>
            <izz>1</izz>
          </inertia>
          <mass>1</mass>
        </inertial>
        <kinematic>0</kinematic>
        <gravity>1</gravity>
      </link>
      <link name='differential_wheel1'>
        <pose frame=''>-0.7 0.35 0.12 3.14159 1.57079 -1.57079</pose>
        <collision name='differential_wheel1_collision'>
          <geometry>
            <cylinder>
              <radius>0.12</radius>
              <length>0.05</length>
            </cylinder>
          </geometry>
          <max_contacts>10</max_contacts>
          <surface>
            <contact>
              <ode/>
            </contact>
            <bounce/>
            <friction>
              <torsional>
                <ode/>
              </torsional>
              <ode/>
            </friction>
          </surface>
        </collision>
        <visual name='differential_wheel1_visual'>
          <geometry>
            <cylinder>
              <radius>0.12</radius>
              <length>0.05</length>
            </cylinder>
          </geometry>
        </visual>
        <self_collide>0</self_collide>
        <inertial>
          <inertia>
            <ixx>1</ixx>
            <ixy>0</ixy>
            <ixz>0</ixz>
            <iyy>1</iyy>
            <iyz>0</iyz>
            <izz>1</izz>
          </inertia>
          <mass>1</mass>
        </inertial>
        <kinematic>0</kinematic>
        <gravity>1</gravity>
      </link>
      <link name='differential_wheel2'>
        <pose frame=''>-0.7 0.25 0.12 3.14159 1.57079 -1.57079</pose>
        <collision name='differential_wheel2_collision'>
          <geometry>
            <cylinder>
              <radius>0.12</radius>
              <length>0.05</length>
            </cylinder>
          </geometry>
          <max_contacts>10</max_contacts>
          <surface>
            <contact>
              <ode/>
            </contact>
            <bounce/>
            <friction>
              <torsional>
                <ode/>
              </torsional>
              <ode/>
            </friction>
          </surface>
        </collision>
        <visual name='differential_wheel2_visual'>
          <geometry>
            <cylinder>
              <radius>0.12</radius>
              <length>0.05</length>
            </cylinder>
          </geometry>
        </visual>
        <self_collide>0</self_collide>
        <inertial>
          <inertia>
            <ixx>1</ixx>
            <ixy>0</ixy>
            <ixz>0</ixz>
            <iyy>1</iyy>
            <iyz>0</iyz>
            <izz>1</izz>
          </inertia>
          <mass>1</mass>
        </inertial>
        <kinematic>0</kinematic>
        <gravity>1</gravity>
      </link>
      <joint name='fix_fork1_mid' type='fixed'>
        <pose frame=''>-0 0 0 0 -0 0</pose>
        <child>mid</child>
        <parent>fork1</parent>
      </joint>
      <joint name='fix_fork2_mid' type='fixed'>
        <pose frame=''>-0 0 0 0 -0 0</pose>
        <child>mid</child>
        <parent>fork2</parent>
      </joint>
      <joint name='fix_diff_body_cylinder' type='fixed'>
        <pose frame=''>-0 0 0 0 -0 0</pose>
        <child>differential_cylinder</child>
        <parent>differential_body</parent>
      </joint>
      <joint name='fix_camera' type='fixed'>
        <pose frame=''>-0 0 0 0 -0 0</pose>
        <child>camera_link</child>
        <parent>mid</parent>
      </joint>
      <joint name='differentialcylinder_mid_z' type='revolute'>
        <pose frame=''>0 0 0 0 -0 0</pose>
        <child>differential_cylinder</child>
        <parent>mid_prismatic</parent>
        <axis>
          <xyz>0 0 1</xyz>
          <limit>
            <effort>10000</effort>
            <lower>-1e+16</lower>
            <upper>1e+16</upper>
          </limit>
          <use_parent_model_frame>1</use_parent_model_frame>
          <dynamics>
            <spring_reference>0</spring_reference>
            <spring_stiffness>0</spring_stiffness>
          </dynamics>
        </axis>
      </joint>
      <joint name='mid_prismatic_joint' type='prismatic'>
        <pose frame=''>0 0 0 0 -0 0</pose>
        <child>mid</child>
        <parent>mid_prismatic</parent>
        <axis>
          <xyz>0 0 1</xyz>
          <limit>
            <upper>0.08</upper>
            <lower>0</lower>
            <velocity>0.0001</velocity>
          </limit>
          <use_parent_model_frame>1</use_parent_model_frame>
          <dynamics>
            <spring_reference>0</spring_reference>
            <spring_stiffness>0</spring_stiffness>
          </dynamics>
        </axis>
      </joint>
      <joint name='differential_wheel1_joint' type='revolute'>
        <pose frame=''>0 0 0 0 -0 0</pose>
        <child>differential_wheel1</child>
        <parent>differential_body</parent>
        <axis>
          <xyz>0 1 0</xyz>
          <use_parent_model_frame>1</use_parent_model_frame>
          <limit>
            <lower>-1e+16</lower>
            <upper>1e+16</upper>
          </limit>
          <dynamics>
            <spring_reference>0</spring_reference>
            <spring_stiffness>0</spring_stiffness>
          </dynamics>
        </axis>
      </joint>
      <joint name='differential_wheel2_joint' type='revolute'>
        <pose frame=''>0 0 0 0 -0 0</pose>
        <child>differential_wheel2</child>
        <parent>differential_body</parent>
        <axis>
          <xyz>0 1 0</xyz>
          <use_parent_model_frame>1</use_parent_model_frame>
          <limit>
            <lower>-1e+16</lower>
            <upper>1e+16</upper>
          </limit>
          <dynamics>
            <spring_reference>0</spring_reference>
            <spring_stiffness>0</spring_stiffness>
          </dynamics>
        </axis>
      </joint>
      <link name='link'>
        <pose frame=''>-0.38 0.3 0.345 0 -0 0</pose>
        <inertial>
          <mass>0.1</mass>
          <inertia>
            <ixx>1</ixx>
            <ixy>0</ixy>
            <ixz>0</ixz>
            <iyy>1</iyy>
            <iyz>0</iyz>
            <izz>1</izz>
          </inertia>
        </inertial>
        <visual name='visual'>
          <geometry>
            <mesh>
              <uri>model://hokuyo/meshes/hokuyo.dae</uri>
              <scale>1 1 1</scale>
            </mesh>
          </geometry>
        </visual>
        <collision name='collision-base'>
          <pose frame=''>0 0 -0.0145 0 -0 0</pose>
          <geometry>
            <box>
              <size>0.05 0.05 0.041</size>
            </box>
          </geometry>
          <max_contacts>10</max_contacts>
          <surface>
            <contact>
              <ode/>
            </contact>
            <bounce/>
            <friction>
              <torsional>
                <ode/>
              </torsional>
              <ode/>
            </friction>
          </surface>
        </collision>
        <collision name='collision-top'>
          <pose frame=''>0 0 0.0205 0 -0 0</pose>
          <geometry>
            <cylinder>
              <radius>0.021</radius>
              <length>0.029</length>
            </cylinder>
          </geometry>
          <max_contacts>10</max_contacts>
          <surface>
            <contact>
              <ode/>
            </contact>
            <bounce/>
            <friction>
              <torsional>
                <ode/>
              </torsional>
              <ode/>
            </friction>
          </surface>
        </collision>
        <sensor name='laser' type='ray'>
          <pose frame=''>0.01 0 0.0175 0 -0 0</pose>
          <ray>
            <scan>
              <horizontal>
                <samples>640</samples>
                <resolution>1</resolution>
                <min_angle>-0.26889</min_angle>
                <max_angle>0.268899</max_angle>
              </horizontal>
              <vertical>
                <samples>1</samples>
                <min_angle>0</min_angle>
                <max_angle>0</max_angle>
              </vertical>
            </scan>
            <range>
              <min>0.02</min>
              <max>0.4</max>
              <resolution>0.01</resolution>
            </range>
          </ray>
          <plugin name='laser' filename='libRayPlugin.so'/>
          <always_on>1</always_on>
          <update_rate>30</update_rate>
          <visualize>1</visualize>
        </sensor>
        <self_collide>0</self_collide>
        <kinematic>0</kinematic>
        <gravity>1</gravity>
      </link>
      <link name='camera_link'>
        <pose frame=''>-0.75 0.3 0.65 0 -0 3.14159</pose>
        <inertial>
          <mass>0.1</mass>
          <inertia>
            <ixx>0.000166667</ixx>
            <iyy>0.000166667</iyy>
            <izz>0.000166667</izz>
            <ixy>0</ixy>
            <ixz>0</ixz>
            <iyz>0</iyz>
          </inertia>
        </inertial>
        <collision name='camera_collision'>
          <geometry>
            <box>
              <size>0.1 0.1 0.1</size>
            </box>
          </geometry>
          <max_contacts>10</max_contacts>
          <surface>
            <contact>
              <ode/>
            </contact>
            <bounce/>
            <friction>
              <torsional>
                <ode/>
              </torsional>
              <ode/>
            </friction>
          </surface>
        </collision>
        <visual name='camera_visual'>
          <geometry>
            <box>
              <size>0.1 0.1 0.1</size>
            </box>
          </geometry>
        </visual>
        <sensor name='camera' type='camera'>
          <camera name='__default__'>
            <horizontal_fov>1.047</horizontal_fov>
            <image>
              <width>320</width>
              <height>240</height>
            </image>
            <clip>
              <near>0.1</near>
              <far>100</far>
            </clip>
          </camera>
          <always_on>1</always_on>
          <update_rate>30</update_rate>
          <visualize>1</visualize>
        </sensor>
        <self_collide>0</self_collide>
        <kinematic>0</kinematic>
        <gravity>1</gravity>
      </link>
      <joint name='hokuyo_joint' type='revolute'>
        <child>link</child>
        <parent>mid</parent>
        <axis>
          <xyz>0 0 1</xyz>
          <limit>
            <upper>0</upper>
            <lower>0</lower>
          </limit>
          <use_parent_model_frame>1</use_parent_model_frame>
          <dynamics>
            <spring_reference>0</spring_reference>
            <spring_stiffness>0</spring_stiffness>
          </dynamics>
        </axis>
      </joint>
      <plugin name='prismatic_plugin' filename='libprismatic_plugin.so'/>
      <plugin name='keyboard_plugin' filename='libkeyboard_plugin.so'/>
      <pose frame=''>-0.604372 -1.77738 0 0 -0 0</pose>
    </model>
    <model name='cube200kg'>
      <self_collide>0</self_collide>
      <static>0</static>
      <link name='cube'>
        <pose frame=''>2 0 0 0 -0 0</pose>
        <inertial>
          <mass>200</mass>
          <inertia>
            <ixx>1</ixx>
            <ixy>0</ixy>
            <ixz>0</ixz>
            <iyy>1</iyy>
            <iyz>0</iyz>
            <izz>1</izz>
          </inertia>
        </inertial>
        <collision name='cube_collision'>
          <pose frame=''>0 0 0.67 0 -0 0</pose>
          <geometry>
            <box>
              <size>1 1 1</size>
            </box>
          </geometry>
          <max_contacts>10</max_contacts>
          <surface>
            <contact>
              <ode/>
            </contact>
            <bounce/>
            <friction>
              <torsional>
                <ode/>
              </torsional>
              <ode/>
            </friction>
          </surface>
        </collision>
        <visual name='cube_visual'>
          <pose frame=''>0 0 0.67 0 -0 0</pose>
          <geometry>
            <box>
              <size>1 1 1</size>
            </box>
          </geometry>
        </visual>
        <collision name='support1_collision'>
          <pose frame=''>0 0.5 0.08 0 -0 0</pose>
          <geometry>
            <box>
              <size>1 0.1 0.16</size>
            </box>
          </geometry>
          <max_contacts>10</max_contacts>
          <surface>
            <contact>
              <ode/>
            </contact>
            <bounce/>
            <friction>
              <torsional>
                <ode/>
              </torsional>
              <ode/>
            </friction>
          </surface>
        </collision>
        <visual name='support1_visual'>
          <pose frame=''>0 0.5 0.08 0 -0 0</pose>
          <geometry>
            <box>
              <size>1 0.1 0.16</size>
            </box>
          </geometry>
        </visual>
        <collision name='support2_collision'>
          <pose frame=''>0 -0.5 0.08 0 -0 0</pose>
          <geometry>
            <box>
              <size>1 0.1 0.16</size>
            </box>
          </geometry>
          <max_contacts>10</max_contacts>
          <surface>
            <contact>
              <ode/>
            </contact>
            <bounce/>
            <friction>
              <torsional>
                <ode/>
              </torsional>
              <ode/>
            </friction>
          </surface>
        </collision>
        <visual name='support2_visual'>
          <pose frame=''>0 -0.5 0.08 0 -0 0</pose>
          <geometry>
            <box>
              <size>1 0.1 0.16</size>
            </box>
          </geometry>
        </visual>
        <collision name='support_mid_collision'>
          <pose frame=''>0 -0.5 0.08 0 -0 0</pose>
          <geometry>
            <box>
              <size>1 0.1 0.16</size>
            </box>
          </geometry>
          <max_contacts>10</max_contacts>
          <surface>
            <contact>
              <ode/>
            </contact>
            <bounce/>
            <friction>
              <torsional>
                <ode/>
              </torsional>
              <ode/>
            </friction>
          </surface>
        </collision>
        <visual name='support_mid_visual'>
          <pose frame=''>0 0 0.08 0 -0 0</pose>
          <geometry>
            <box>
              <size>1 0.1 0.16</size>
            </box>
          </geometry>
        </visual>
        <self_collide>0</self_collide>
        <kinematic>0</kinematic>
        <gravity>1</gravity>
      </link>
      <pose frame=''>-1.45807 -1.47613 0 0 -0 0</pose>
    </model>
    <state world_name='default'>
      <sim_time>6 440000000</sim_time>
      <real_time>15 428741540</real_time>
      <wall_time>1492983467 422433253</wall_time>
      <iterations>6440</iterations>
      <model name='Jack2'>
        <pose frame=''>-0.604353 -1.77731 -3e-06 -2e-06 4e-06 -6.8e-05</pose>
        <scale>1 1 1</scale>
        <link name='camera_link'>
          <pose frame=''>-1.35432 -1.47726 0.649987 2e-06 -2.1e-05 3.14152</pose>
          <velocity>0.000994 3.9e-05 0.001063 -5.5e-05 0.005714 -2.5e-05</velocity>
          <acceleration>1.20452 0.068147 2.28534 3.043 -0.620765 3.1282</acceleration>
          <wrench>0.120452 0.006815 0.228534 0 -0 0</wrench>
        </link>
        <link name='differential_body'>
          <pose frame=''>-1.30433 -1.47726 0.12 -2e-06 4e-06 3.2e-05</pose>
          <velocity>-3.3e-05 1.1e-05 0.005164 -4.7e-05 0.000635 5e-06</velocity>
          <acceleration>-0.060648 -0.013175 10.3274 -0.105624 0.234673 -0.000102</acceleration>
          <wrench>-0.060648 -0.013175 10.3274 0 -0 0</wrench>
        </link>
        <link name='differential_cylinder'>
          <pose frame=''>-1.30433 -1.47726 0.3825 -2e-06 4e-06 3.2e-05</pose>
          <velocity>0.00014 3.4e-05 0.005106 -6e-05 0.000638 5e-06</velocity>
          <acceleration>0.011889 0.034669 10.2087 -0.131259 0.23674 -3.5e-05</acceleration>
          <wrench>0.011889 0.034669 10.2087 0 -0 0</wrench>
        </link>
        <link name='differential_wheel1'>
          <pose frame=''>-1.30433 -1.42726 0.12 -1.57463 1.56864 -0.003791</pose>
          <velocity>-4e-05 4e-06 0.005186 -3.3e-05 -0.000335 5e-06</velocity>
          <acceleration>-0.071795 -0.028045 10.3723 -0.077209 -0.002202 -9.4e-05</acceleration>
          <wrench>-0.071795 -0.028045 10.3723 0 -0 0</wrench>
        </link>
        <link name='differential_wheel2'>
          <pose frame=''>-1.30433 -1.52726 0.12 -1.57472 1.56868 -0.00388</pose>
          <velocity>-3.9e-05 5e-06 0.005153 -4.5e-05 -0.000326 5e-06</velocity>
          <acceleration>-0.07109 -0.02536 10.3047 -0.099565 0.005423 -0.000558</acceleration>
          <wrench>-0.07109 -0.02536 10.3047 0 -0 0</wrench>
        </link>
        <link name='fork1'>
          <pose frame=''>-0.604352 -1.77731 0.119997 -2e-06 4e-06 -6.8e-05</pose>
          <velocity>1.5e-05 1.6e-05 0.004503 -1.5e-05 0.000537 -1.2e-05</velocity>
          <acceleration>0.034245 0.011077 9.69256 -0.033776 0.08822 -0.003157</acceleration>
          <wrench>0.034245 0.011077 9.69256 0 -0 0</wrench>
        </link>
        <link name='fork1_prismatic_cylinder_bottom'>
          <pose frame=''>-0.124352 -1.77734 0.079997 2.33411 1.57079 -2.37833</pose>
          <velocity>-1e-05 9e-06 0.004395 -1.5e-05 1e-06 -1.2e-05</velocity>
          <acceleration>0.027523 0.007308 9.34087 -0.033465 0.00169 -0.003163</acceleration>
          <wrench>0.027523 0.007308 9.34087 0 -0 0</wrench>
        </link>
        <link name='fork1_prismatic_cylinder_top'>
          <pose frame=''>-0.124352 -1.77734 0.089997 2.32964 1.57079 -2.38281</pose>
          <velocity>-1e-05 8e-06 0.004741 -1e-06 1e-06 -1.2e-05</velocity>
          <acceleration>0.033927 0.004544 10.482 -0.004896 0.001688 -0.003475</acceleration>
          <wrench>0.033927 0.004544 10.482 0 -0 0</wrench>
        </link>
        <link name='fork1_wheel'>
          <pose frame=''>-0.004352 -1.77735 0.070001 1.57478 1.56888 -3.13767</pose>
          <velocity>2.1e-05 -5e-06 0.005086 7.4e-05 0.000297 -1.3e-05</velocity>
          <acceleration>0.083159 -0.019751 10.176 0.148671 -0.008211 -0.005202</acceleration>
          <wrench>0.083159 -0.019751 10.176 0 -0 0</wrench>
        </link>
        <link name='fork1_wheelholder'>
          <pose frame=''>-0.204352 -1.77734 0.069997 -2e-06 -1.5e-05 -6.8e-05</pose>
          <velocity>9e-06 9e-06 0.004392 -3e-06 -0.001927 -1.2e-05</velocity>
          <acceleration>0.044124 0.005624 9.51266 -0.008663 -0.910988 -0.003342</acceleration>
          <wrench>0.044124 0.005624 9.51266 0 -0 0</wrench>
        </link>
        <link name='fork2'>
          <pose frame=''>-0.604312 -1.17731 0.119996 -2e-06 4e-06 -6.8e-05</pose>
          <velocity>6e-06 1.7e-05 0.004493 -4.6e-05 0.000557 -1.2e-05</velocity>
          <acceleration>0.0021 0.013942 9.6972 -0.101457 0.097792 -0.002928</acceleration>
          <wrench>0.0021 0.013942 9.6972 0 -0 0</wrench>
        </link>
        <link name='fork2_prismatic_cylinder_bottom'>
          <pose frame=''>-0.124312 -1.17734 0.079997 2.302 1.57078 -2.41045</pose>
          <velocity>-2e-05 9e-06 0.004364 -4.5e-05 1e-06 -1.2e-05</velocity>
          <acceleration>-0.003028 0.00675 9.25617 -0.097701 0.001209 -0.003126</acceleration>
          <wrench>-0.003028 0.00675 9.25617 0 -0 0</wrench>
        </link>
        <link name='fork2_prismatic_cylinder_top'>
          <pose frame=''>-0.124312 -1.17734 0.089996 2.29794 1.57078 -2.4145</pose>
          <velocity>-2.1e-05 8e-06 0.004752 -3.1e-05 1e-06 -1.2e-05</velocity>
          <acceleration>0.002016 0.005583 10.5659 -0.070809 0.001207 -0.003286</acceleration>
          <wrench>0.002016 0.005583 10.5659 0 -0 0</wrench>
        </link>
        <link name='fork2_wheel'>
          <pose frame=''>-0.004312 -1.17735 0.070001 1.58313 1.57016 -3.12932</pose>
          <velocity>7e-06 -3e-06 0.005103 4.4e-05 9.3e-05 -1.3e-05</velocity>
          <acceleration>0.040226 -0.014851 10.2098 0.081012 -0.013503 -0.004419</acceleration>
          <wrench>0.040226 -0.014851 10.2098 0 -0 0</wrench>
        </link>
        <link name='fork2_wheelholder'>
          <pose frame=''>-0.204312 -1.17734 0.069996 -2e-06 -1.7e-05 -6.8e-05</pose>
          <velocity>-1e-06 9e-06 0.004371 -3.4e-05 -0.001948 -1.2e-05</velocity>
          <acceleration>0.010141 0.005527 9.47956 -0.075748 -0.736738 -0.003146</acceleration>
          <wrench>0.010141 0.005527 9.47956 0 -0 0</wrench>
        </link>
        <link name='link'>
          <pose frame=''>-0.984331 -1.47728 0.344998 -2e-06 4e-06 -6.8e-05</pose>
          <velocity>0.000144 3.9e-05 0.004701 -4.8e-05 0.000568 2e-06</velocity>
          <acceleration>0.052116 0.050951 9.71078 -0.101159 0.125207 0.026667</acceleration>
          <wrench>0.005212 0.005095 0.971078 0 -0 0</wrench>
        </link>
        <link name='mid'>
          <pose frame=''>-1.05433 -1.47728 0.344998 -2e-06 4e-06 -6.8e-05</pose>
          <velocity>0.000146 3.7e-05 0.004762 -3.4e-05 0.000563 -1.1e-05</velocity>
          <acceleration>0.056529 0.045605 9.75978 -0.072569 0.124669 -0.001463</acceleration>
          <wrench>0.056529 0.045605 9.75978 0 -0 0</wrench>
        </link>
        <link name='mid_prismatic'>
          <pose frame=''>-1.05433 -1.47728 0.344999 -2e-06 4e-06 -6.8e-05</pose>
          <velocity>0.000126 3.5e-05 0.004894 -6.7e-05 0.000635 -9e-06</velocity>
          <acceleration>0.018239 0.042705 10.0361 -0.143378 0.233018 0.003054</acceleration>
          <wrench>0.018239 0.042705 10.0361 0 -0 0</wrench>
        </link>
      </model>
      <model name='cube200kg'>
        <pose frame=''>-1.45807 -1.47613 0 0 -0 0</pose>
        <scale>1 1 1</scale>
        <link name='cube'>
          <pose frame=''>0.54193 -1.47613 0 0 -0 0</pose>
          <velocity>0 0 0 0 -0 0</velocity>
          <acceleration>-1.1e-05 1.9e-05 10.3141 2.11855 -0.146995 4e-06</acceleration>
          <wrench>-0.002155 0.003849 2062.82 0 -0 0</wrench>
        </link>
      </model>
      <model name='ground_plane'>
        <pose frame=''>0 0 0 0 -0 0</pose>
        <scale>1 1 1</scale>
        <link name='link'>
          <pose frame=''>0 0 0 0 -0 0</pose>
          <velocity>0 0 0 0 -0 0</velocity>
          <acceleration>0 0 0 0 -0 0</acceleration>
          <wrench>0 0 0 0 -0 0</wrench>
        </link>
      </model>
      <light name='sun'>
        <pose frame=''>0 0 10 0 -0 0</pose>
      </light>
    </state>
    <gui fullscreen='0'>
      <camera name='user_camera'>
        <pose frame=''>-4.32926 -4.97267 1.94848 0 0.265797 0.956195</pose>
        <view_controller>orbit</view_controller>
        <projection_type>perspective</projection_type>
      </camera>
    </gui>
  </world>
</sdf>
